<?xml version="1.0" ?>
<!-- =================================================================================== -->
<!-- |    This document was autogenerated by xacro from robot.xacro                    | -->
<!-- |    EDITING THIS FILE BY HAND IS NOT RECOMMENDED                                 | -->
<!-- =================================================================================== -->
<robot name="aliengo">
  <material name="black">
    <color rgba="0.0 0.0 0.0 1.0"/>
  </material>
  <material name="blue">
    <color rgba="1.0 1.0 1.0 1.0"/>
  </material>
  <material name="green">
    <color rgba="0.749 1 0.647 0.831" />
  </material>
  <material name="head">
    <color rgba="1 0.267 0.267 1.0" />
  </material>
  <material name="grey">
    <color rgba="0.6 0.569 0.769 0.78" />
  </material>
  <material name="silver">
    <color rgba=" 0.227 0.227 0.231 0.831" />
  </material>
  <material name="orange">
    <!-- <color rgba="1.0 0.423529411765 0.0392156862745 0.2" /> -->
    <color rgba="0.12 0.15 0.2 0.2" />
  </material>
  <material name="brown">
    <color rgba="0.870588235294 0.811764705882 0.764705882353 0.2" />
  </material>
  <material name="white">
    <color rgba="1 0.267 0.267 1.0" />
  </material>

  <link name="base">
    <visual>
      <origin rpy="0 0 0" xyz="0 0 0"/>
      <geometry>
        <box size="0.001 0.001 0.001"/>
      </geometry>
    </visual>
  </link>
  <joint name="floating_base" type="fixed" dont_collapse="true">
    <origin rpy="0 0 0" xyz="0 0 0"/>
    <parent link="base"/>
    <child link="trunk"/>
  </joint>

  <link name="trunk1">
    <visual>
      <origin rpy="0 0 0" xyz="0 0 0"/>
      <geometry>
        <sphere radius="0.0921" />
      </geometry>
      <material name="white"/>
    </visual>
    <!-- <collision>
      <origin rpy="0 0 0" xyz="0 0 0"/>
      <geometry>
        <sphere radius="0.1" />
      </geometry>
    </collision> -->
    <inertial>
      <origin rpy="0 0 0" xyz="0.012731 0.002186 0.000515"/>
      <mass value="0.313"/>
      <inertia ixx="0.00001683993" ixy="8.3902e-08" ixz="0.00000597679" iyy="0.000001060" iyz="2.5134e-08" izz="0.0000064713601"/>
    </inertial>
  </link>
  <joint name="trunk1_joint" type="fixed" dont_collapse="true">
    <origin rpy="0 0.0 0" xyz="0.1295 0 0"/>
    <parent link="trunk2"/>
    <child link="trunk1"/>
    <axis xyz="1 0 0"/>
    <dynamics damping="0" friction="0"/>
    <limit effort="3000.5"   velocity="100000"/> 
  </joint>
  <link name="trunk2">
    <visual>
      <origin rpy="0 0 0" xyz="0 0 -0.035"/>
      <geometry>
        <sphere radius="0.0595" />
      </geometry>
      <material name="white"/>
    </visual>
    <!-- <collision>
      <origin rpy="0 0 0" xyz="0 0 0"/>
      <geometry>
        <sphere radius="0.2" />
      </geometry>
    </collision> -->
    <inertial>
      <origin rpy="0 0 0" xyz="0.012731 0.002186 0.000515"/>
      <mass value="0.13"/>
      <inertia ixx="0.00001683993" ixy="8.3902e-08" ixz="0.00000597679" iyy="0.000001060" iyz="2.5134e-08" izz="0.0000064713601"/>
    </inertial>
  </link>
  <joint name="trunk2_joint" type="fixed" dont_collapse="true">
    <origin rpy="0 0 0" xyz="0.098 0 0"/>
    <parent link="trunk"/>
    <child link="trunk2"/>
    <axis xyz="1 0 0"/>
    <dynamics damping="0" friction="0"/>
    <limit effort="3000.5"   velocity="100000"/> 
  </joint>
  <link name="trunk">
    <visual>
      <origin rpy="0 0 0" xyz="0 0 -0.023"/>
      <geometry>
        <sphere radius="0.07" />
      </geometry>
      <material name="silver"/>
    </visual>
    <collision>
      <origin rpy="0 0 0" xyz="0 0 0"/>
      <geometry>
        <sphere radius="0.21" />
      </geometry>
    </collision>
    <inertial>
      <origin rpy="0 0 0" xyz="0.012731 0.002186 0.000515"/>
      <mass value="1.713"/>
      <inertia ixx="0.01683993" ixy="8.3902e-05" ixz="0.000597679" iyy="0.106579028" iyz="2.5134e-05" izz="0.064713601"/>
    </inertial>
  </link>
  <joint name="trunk3_joint" type="fixed" dont_collapse="true">
    <origin rpy="0 0 0" xyz="-0.091 0 0"/>
    <parent link="trunk"/>
    <child link="trunk4"/>
    <axis xyz="1 0 0"/>
    <dynamics damping="0" friction="0"/>
    <limit effort="3000.5"   velocity="100000"/> 
  </joint>
  <link name="trunk4">
    <visual>
      <origin rpy="0 0 0" xyz="0 0 0"/>
      <geometry>
        <sphere radius="0.048" />
      </geometry>
      <material name="white"/>
    </visual>
    <!-- <collision>
      <origin rpy="0 0 0" xyz="0 0 0"/>
      <geometry>
        <sphere radius="0.1" />
      </geometry>
    </collision> -->
    <inertial>
      <origin rpy="0 0 0" xyz="0.012731 0.002186 0.000515"/>
      <mass value="0.613"/>
      <inertia ixx="0.00001683993" ixy="8.3902e-08" ixz="0.00000597679" iyy="0.000001060" iyz="2.5134e-08" izz="0.0000064713601"/>
    </inertial>
  </link>
  <joint name="trunk4_joint" type="fixed" dont_collapse="true">
    <origin rpy="0 0 0" xyz="-0.077 0 0"/>
    <parent link="trunk4"/>
    <child link="trunk5"/>
    <axis xyz="1 0 0"/>
    <dynamics damping="0" friction="0"/>
    <limit effort="3000.5"   velocity="100000"/> 
  </joint>
  <link name="trunk5">
    <visual>
      <origin rpy="0 0 0" xyz="0 0 0"/>
      <geometry>
        <sphere radius="0.056" />
      </geometry>
      <material name="silver"/>
    </visual>
    <!-- <collision>
      <origin rpy="0 0 0" xyz="0 0 0"/>
      <geometry>
        <sphere radius="0.1" />
      </geometry>
    </collision> -->
    <inertial>
      <origin rpy="0 0 0" xyz="0.012731 0.002186 0.000515"/>
      <mass value="0.313"/>
      <inertia ixx="0.00001683993" ixy="8.3902e-08" ixz="0.00000597679" iyy="0.000001060" iyz="2.5134e-08" izz="0.0000064713601"/>
    </inertial>
  </link>
  <joint name="trunk5_joint" type="fixed" dont_collapse="true">
    <origin rpy="0 0 0" xyz="-0.042 0 0"/>
    <parent link="trunk5"/>
    <child link="trunk6"/>
    <axis xyz="1 0 0"/>
    <dynamics damping="0" friction="0"/>
    <limit effort="3000.5"   velocity="100000"/> 
  </joint>
  <link name="trunk6">
    <visual>
      <origin rpy="0 0 0" xyz="0 0 0"/>
      <geometry>
        <sphere radius="0.084" />
      </geometry>
      <material name="white"/>
    </visual>
    <!-- <collision>
      <origin rpy="0 0 0" xyz="0 0 0"/>
      <geometry>
        <sphere radius="0.1" />
      </geometry>
    </collision> -->
    <inertial>
      <origin rpy="0 0 0" xyz="0.012731 0.002186 0.000515"/>
      <mass value="0.313"/>
      <inertia ixx="0.00001683993" ixy="8.3902e-08" ixz="0.00000597679" iyy="0.000001060" iyz="2.5134e-08" izz="0.0000064713601"/>
    </inertial>
  </link>
    <joint name="neck1_joint" type="fixed" dont_collapse="true">
    <origin rpy="0 0 0" xyz="0.071 0 0.10"/>
    <parent link="trunk1"/>
    <child link="neck1"/>
    <axis xyz="1 0 0"/>
    <dynamics damping="0" friction="0"/>
    <limit effort="3000.5"   velocity="100000"/> 
  </joint>
  <link name="neck1">
    <visual>
      <origin rpy="0 0 0" xyz="0 0 0"/>
      <geometry>
        <sphere radius="0.038" />
      </geometry>
      <material name="white"/>
    </visual>
    <!-- <collision>
      <origin rpy="0 0 0" xyz="0 0 0"/>
      <geometry>
        <sphere radius="0.2" />
      </geometry>
    </collision> -->
    <inertial>
      <origin rpy="0 0 0" xyz="0.003311 0.000635 3.1e-05"/>
      <mass value="0.07"/>
      <inertia ixx="0.000469246" ixy="9.409e-06" ixz="3.42e-07" iyy="0.00080749" iyz="-4.66e-07" izz="0.000552929"/>
    </inertial>
  </link>

    <joint name="neck2_joint" type="fixed" dont_collapse="true">
    <origin rpy="0 -0.497 0" xyz="0.038 0 0.0321"/>
    <parent link="neck1"/>
    <child link="neck2"/>
    <axis xyz="1 0 0"/>
    <dynamics damping="0" friction="0"/>
    <limit effort="3000.5"   velocity="100000"/> 
  </joint>
  <link name="neck2">
    <visual>
      <origin rpy="0 1.57 0" xyz="0 0 0"/>
      <geometry>
         <cylinder length="0.050" radius="0.023"/>
      </geometry>
      <material name="silver"/>
    </visual>
    <!-- <collision>
      <origin rpy="0 0 0" xyz="0 0 0"/>
      <geometry>
        <sphere radius="0.2" />
      </geometry>
    </collision> -->
    <inertial>
      <origin rpy="0 0 0" xyz="0.003311 0.000635 3.1e-05"/>
      <mass value="0.15"/>
      <inertia ixx="0.000469246" ixy="9.409e-06" ixz="3.42e-07" iyy="0.00080749" iyz="-4.66e-07" izz="0.000552929"/>
    </inertial>
  </link>
  <joint name="neck3_joint" type="fixed" dont_collapse="true">
    <origin rpy="0 0 0" xyz="0.059 0 0.0"/>
    <parent link="neck2"/>
    <child link="neck3"/>
    <axis xyz="1 0 0"/>
    <dynamics damping="0" friction="0"/>
    <limit effort="3000.5"   velocity="100000"/> 
  </joint>
  <link name="neck3">
    <visual>
      <origin rpy="0 0 0" xyz="0 0 0"/>
      <geometry>
        <sphere radius="0.029" />
      </geometry>
      <material name="white"/>
    </visual>
    <!-- <collision>
      <origin rpy="0 0 0" xyz="0 0 0"/>
      <geometry>
        <sphere radius="0.2" />
      </geometry>
    </collision> -->
    <inertial>
      <origin rpy="0 0 0" xyz="0.003311 0.000635 3.1e-05"/>
      <mass value="0.072"/>
      <inertia ixx="0.000469246" ixy="9.409e-06" ixz="3.42e-07" iyy="0.00080749" iyz="-4.66e-07" izz="0.000552929"/>
    </inertial>
  </link>
  <joint name="neck4_joint" type="fixed" dont_collapse="true">
    <origin rpy="0 0 0" xyz="-0.021 0 0.01"/>
    <parent link="neck3"/>
    <child link="head"/>
    <axis xyz="1 0 0"/>
    <dynamics damping="0" friction="0"/>
    <limit effort="3000.5"   velocity="100000"/> 
  </joint>
  <link name="head">
    <visual>
      <origin rpy="0 -0.35 0" xyz="0.08 0 0"/>
      <geometry>
        <box size="0.1 0.12 0.15"/>
      </geometry>
      <material name="head"/>
    </visual>
    <!-- <collision>
      <origin rpy="0 0 0" xyz="0 0 0"/>
      <geometry>
        <sphere radius="0.2" />
      </geometry>
    </collision> -->
    <inertial>
      <origin rpy="0 0 0" xyz="0.003311 0.000635 3.1e-05"/>
      <mass value="0.1"/>
      <inertia ixx="0.000469246" ixy="9.409e-06" ixz="3.42e-07" iyy="0.00080749" iyz="-4.66e-07" izz="0.000552929"/>
    </inertial>
  </link>

    <joint name="tail1_joint" type="fixed" dont_collapse="true">
    <origin rpy="0 0.07 0" xyz="-0.105 0 0"/>
    <parent link="trunk6"/>
    <child link="tail1"/>
    <axis xyz="0 1 0"/>
    <dynamics damping="0" friction="0"/>
    <limit effort="3000.5"   velocity="100000"/> 
  </joint>
  <link name="tail1">
    <visual>
      <origin rpy="0 1.57 0" xyz="0 0 0"/>
      <geometry>
        <cylinder length="0.105" radius="0.024"/>
      </geometry>
      <material name="silver"/>
    </visual>
    <!-- <collision>
      <origin rpy="0 0 0" xyz="0 0 0"/>
      <geometry>
        <cylinder length="0.15" radius="0.0883"/>
      </geometry>
    </collision> -->
    <inertial>
      <origin rpy="0 0 0" xyz="0.003311 0.000635 3.1e-05"/>
      <mass value="0.1"/>
      <inertia ixx="0.000469246" ixy="9.409e-06" ixz="3.42e-07" iyy="0.00080749" iyz="-4.66e-07" izz="0.000552929"/>
    </inertial>
  </link>

    <joint name="tail11_joint" type="fixed" dont_collapse="true">
    <origin rpy="0 0.035 0" xyz="-0.079 -0.0 -0."/>
    <parent link="tail1"/>
    <child link="tail11"/>
    <axis xyz="0 1 0"/>
    <dynamics damping="0" friction="0"/>
    <limit effort="3000.5"   velocity="100000"/> 
  </joint>

  <link name="tail11">
    <visual>
      <origin rpy="0 0 0" xyz="0 0 0"/>
      <geometry>
        <sphere radius="0.0175" />
      </geometry>
      <material name="silver"/>
    </visual>
    <!-- <collision>
      <origin rpy="0 0 0" xyz="0 0 0"/>
      <geometry>
        <cylinder length="0.15" radius="0.0883"/>
      </geometry>
    </collision> -->
    <inertial>
      <origin rpy="0 0 0" xyz="0.003311 0.000635 3.1e-05"/>
      <mass value="0.105"/>
      <inertia ixx="0.000469246" ixy="9.409e-06" ixz="3.42e-07" iyy="0.00080749" iyz="-4.66e-07" izz="0.000552929"/>
    </inertial>
  </link>
  <joint name="tail2_joint" type="fixed" dont_collapse="true">
    <origin rpy="0 0 0" xyz="-0.056 -0.0 -0."/>
    <parent link="tail11"/>
    <child link="tail2"/>
    <axis xyz="0 1 0"/>
    <dynamics damping="0" friction="0"/>
    <limit effort="3000.5"   velocity="100000"/> 
  </joint>
  <link name="tail2">
    <visual>
      <origin rpy="0 1.57 0" xyz="0 0 0"/>
      <geometry>
        <cylinder length="0.0935" radius="0.0168415"/>
      </geometry>
      <material name="white"/>
    </visual>
    <!-- <collision>
      <origin rpy="0 0 0" xyz="0 0 0"/>
      <geometry>
        <cylinder length="0.15" radius="0.0883"/>
      </geometry>
    </collision> -->
    <inertial>
      <origin rpy="0 0 0" xyz="0.003311 0.000635 3.1e-05"/>
      <mass value="0.105"/>
      <inertia ixx="0.000469246" ixy="9.409e-06" ixz="3.42e-07" iyy="0.00080749" iyz="-4.66e-07" izz="0.000552929"/>
    </inertial>
  </link>
    <joint name="tail22_joint" type="fixed" dont_collapse="true">
    <origin rpy="0 0 0" xyz="-0.063 -0.0 -0."/>
    <parent link="tail2"/>
    <child link="tail22"/>
    <axis xyz="0 1 0"/>
    <dynamics damping="0" friction="0"/>
    <limit effort="3000.5"   velocity="100000"/> 
  </joint>
  <link name="tail22">
    <visual>
      <origin rpy="0 0 0" xyz="0 0 0"/>
      <geometry>
        <sphere radius="0.0153" />
      </geometry>
      <material name="silver"/>
    </visual>
    <!-- <collision>
      <origin rpy="0 0 0" xyz="0 0 0"/>
      <geometry>
        <cylinder length="0.15" radius="0.0883"/>
      </geometry>
    </collision> -->
    <inertial>
      <origin rpy="0 0 0" xyz="0.003311 0.000635 3.1e-05"/>
      <mass value="0.105"/>
      <inertia ixx="0.000469246" ixy="9.409e-06" ixz="3.42e-07" iyy="0.00080749" iyz="-4.66e-07" izz="0.000552929"/>
    </inertial>
  </link>
  <joint name="tail3_joint" type="fixed" dont_collapse="true">
    <origin rpy="0 0.0 0" xyz="-0.032 -0.0 0.000"/>
    <parent link="tail22"/>
    <child link="tail3"/>
    <axis xyz="0 1 0"/>
    <dynamics damping="0" friction="0"/>
    <limit effort="3000.5"   velocity="100000"/> 
  </joint>
  <link name="tail3">
    <visual>
      <origin rpy="0 1.57 0" xyz="0 0 0"/>
      <geometry>
        <cylinder length="0.0795" radius="0.0133515"/>
      </geometry>
      <material name="silver"/>
    </visual>
    <!-- <collision>
      <origin rpy="0 0 0" xyz="0 0 0"/>
      <geometry>
        <cylinder length="0.15" radius="0.0883"/>
      </geometry>
    </collision> -->
    <inertial>
      <origin rpy="0 0 0" xyz="0.003311 0.000635 3.1e-05"/>
      <mass value="0.1"/>
      <inertia ixx="0.000469246" ixy="9.409e-06" ixz="3.42e-07" iyy="0.00080749" iyz="-4.66e-07" izz="0.000552929"/>
    </inertial>
  </link>


  <link name="FR_hip">
    <visual>
      <origin rpy="0 0 0" xyz="0 0 0"/>
      <geometry>
        <sphere radius="0.042" />
      </geometry>
      <material name="black"/>
    </visual>
    <!-- <collision>
      <origin rpy="0 0 0" xyz="0 0 0"/>
      <geometry>
        <sphere radius="0.2" />
      </geometry>
    </collision> -->
    <inertial>
      <origin rpy="0 0 0" xyz="-0.022191 -0.015144 -1.5e-05"/>
      <mass value="1.993"/>
      <inertia ixx="0.002446735" ixy="0.00059805" ixz="1.945e-06" iyy="0.003925876" iyz="-1.284e-06" izz="0.004148145"/>
    </inertial>
  </link>

  <link name="FR_thigh">
    <visual>
      <origin rpy="0 0 0" xyz="0 0 -0.12"/>
      <geometry>
         <cylinder length="0.24" radius="0.028015"/>
      </geometry>
      <material name="silver"/>
    </visual>

    <inertial>
      <origin rpy="0 0 0" xyz="-0.005607 0.003877 -0.048199"/>
      <mass value="0.639"/>
      <inertia ixx="0.004173855" ixy="-1.0284e-05" ixz="-0.000318874" iyy="0.004343802" iyz="-0.000109233" izz="0.000340136"/>
    </inertial>
  </link>


  <link name="FR_calf">
    <visual>
      <origin rpy="0 0 0" xyz="0 0 -0.12" />
      <geometry>
         <cylinder length="0.24" radius="0.02015"/>
      </geometry>
      <material name="blue"/>
    </visual>
    <inertial>
      <origin rpy="0 0 0" xyz="0.002781 6.3e-05 -0.142518"/>
      <mass value="0.207"/>
      <inertia ixx="0.002129279" ixy="3.9e-08" ixz="5.757e-06" iyy="0.002141463" iyz="-5.16e-07" izz="3.7583e-05"/>
    </inertial>
  </link>


  <link name="FR_foot">
    <visual>
      <origin rpy="0 0 0" xyz="0 0 0"/>
      <geometry>
        <sphere radius="0.0165"/>
      </geometry>
      <material name="green"/>
    </visual>
    <collision>
      <origin rpy="0 0 0" xyz="0 0 0"/>
      <geometry>
        <sphere radius="0.0265"/>
      </geometry>
    </collision>
    <inertial>
      <mass value="0.06"/>
      <inertia ixx="1.6853999999999998e-05" ixy="0.0" ixz="0.0" iyy="1.6853999999999998e-05" iyz="0.0" izz="1.6853999999999998e-05"/>
    </inertial>
  </link>



  <link name="FL_hip">
    <visual>
      <origin rpy="0 0 0" xyz="0 0 0"/>
      <geometry>
        <sphere radius="0.042" />
      </geometry>
      <material name="black"/>
    </visual>
    <inertial>
      <origin rpy="0 0 0" xyz="-0.022191 0.015144 -1.5e-05"/>
      <mass value="1.993"/>
      <inertia ixx="0.002446735" ixy="-0.00059805" ixz="1.945e-06" iyy="0.003925876" iyz="1.284e-06" izz="0.004148145"/>
    </inertial>
  </link>

  <link name="FL_thigh">
    <visual>
      <origin rpy="0 0 0" xyz="0 0 -0.12"/>
      <geometry>
         <cylinder length="0.24" radius="0.028015"/>
      </geometry>
      <material name="silver"/>
    </visual>
    <inertial>
      <origin rpy="0 0 0" xyz="-0.005607 -0.003877 -0.048199"/>
      <mass value="0.639"/>
      <inertia ixx="0.004173855" ixy="1.0284e-05" ixz="-0.000318874" iyy="0.004343802" iyz="0.000109233" izz="0.000340136"/>
    </inertial>
  </link>



  <link name="FL_calf">
    <visual>
      <origin rpy="0 0 0" xyz="0 0 -0.12" />
      <geometry>
         <cylinder length="0.24" radius="0.02015"/>
      </geometry>
      <material name="blue"/>
    </visual>
    <inertial>
      <origin rpy="0 0 0" xyz="0.002781 6.3e-05 -0.142518"/>
      <mass value="0.207"/>
      <inertia ixx="0.002129279" ixy="3.9e-08" ixz="5.757e-06" iyy="0.002141463" iyz="-5.16e-07" izz="3.7583e-05"/>
    </inertial>
  </link>


  <link name="FL_foot">
    <visual>
      <origin rpy="0 0 0" xyz="0 0 0"/>
      <geometry>
        <sphere radius="0.0165"/>
      </geometry>
      <material name="green"/>
    </visual>
    <collision>
      <origin rpy="0 0 0" xyz="0 0 0"/>
      <geometry>
        <sphere radius="0.0265"/>
      </geometry>
    </collision>
    <inertial>
      <mass value="0.06"/>
      <inertia ixx="1.6853999999999998e-05" ixy="0.0" ixz="0.0" iyy="1.6853999999999998e-05" iyz="0.0" izz="1.6853999999999998e-05"/>
    </inertial>
  </link>

  <link name="RR_hip">
    <visual>
      <origin rpy="0 0 0" xyz="0 0 0"/>
      <geometry>
        <sphere radius="0.042" />
      </geometry>
      <material name="black"/>
    </visual>
    <inertial>
      <origin rpy="0 0 0" xyz="0.022191 -0.015144 -1.5e-05"/>
      <mass value="1.993"/>
      <inertia ixx="0.002446735" ixy="-0.00059805" ixz="-1.945e-06" iyy="0.003925876" iyz="-1.284e-06" izz="0.004148145"/>
    </inertial>
  </link>
 

  <link name="RR_thigh">
    <visual>
      <origin rpy="0 0 0" xyz="0 0 -0.12"/>
      <geometry>
         <cylinder length="0.24" radius="0.028015"/>
      </geometry>
      <material name="silver"/>
    </visual>
    <inertial>
      <origin rpy="0 0 0" xyz="-0.005607 0.003877 -0.048199"/>
      <mass value="0.639"/>
      <inertia ixx="0.004173855" ixy="-1.0284e-05" ixz="-0.000318874" iyy="0.004343802" iyz="-0.000109233" izz="0.000340136"/>
    </inertial>
  </link>
 

  <link name="RR_calf">
    <visual>
      <origin rpy="0 0 0" xyz="0 0 -0.12" />
      <geometry>
         <cylinder length="0.24" radius="0.02015"/>
      </geometry>
      <material name="blue"/>
    </visual>
    <inertial>
      <origin rpy="0 0 0" xyz="0.002781 6.3e-05 -0.142518"/>
      <mass value="0.207"/>
      <inertia ixx="0.002129279" ixy="3.9e-08" ixz="5.757e-06" iyy="0.002141463" iyz="-5.16e-07" izz="3.7583e-05"/>
    </inertial>
  </link>
 
  <link name="RR_foot">
    <visual>
      <origin rpy="0 0 0" xyz="0 0 0"/>
      <geometry>
        <sphere radius="0.0165"/>
      </geometry>
      <material name="green"/>
    </visual>
    <collision>
      <origin rpy="0 0 0" xyz="0 0 0"/>
      <geometry>
        <sphere radius="0.0265"/>
      </geometry>
    </collision>
    <inertial>
      <mass value="0.06"/>
      <inertia ixx="1.6853999999999998e-05" ixy="0.0" ixz="0.0" iyy="1.6853999999999998e-05" iyz="0.0" izz="1.6853999999999998e-05"/>
    </inertial>
  </link>


  <link name="RL_hip">
    <visual>
      <origin rpy="0 0 0" xyz="0 0 0"/>
      <geometry>
        <sphere radius="0.042" />
      </geometry>
      <material name="black"/>
    </visual>
    <inertial>
      <origin rpy="0 0 0" xyz="0.022191 0.015144 -1.5e-05"/>
      <mass value="1.993"/>
      <inertia ixx="0.002446735" ixy="0.00059805" ixz="-1.945e-06" iyy="0.003925876" iyz="1.284e-06" izz="0.004148145"/>
    </inertial>
  </link>


  <link name="RL_thigh">
    <visual>
      <origin rpy="0 0 0" xyz="0 0 -0.12"/>
      <geometry>
         <cylinder length="0.24" radius="0.028015"/>
      </geometry>
      <material name="silver"/>
    </visual>
    <inertial>
      <origin rpy="0 0 0" xyz="-0.005607 -0.003877 -0.048199"/>
      <mass value="0.639"/>
      <inertia ixx="0.004173855" ixy="1.0284e-05" ixz="-0.000318874" iyy="0.004343802" iyz="0.000109233" izz="0.000340136"/>
    </inertial>
  </link>


  <link name="RL_calf">
    <visual>
      <origin rpy="0 0 0" xyz="0 0 -0.12" />
      <geometry>
         <cylinder length="0.24" radius="0.02015"/>
      </geometry>
      <material name="blue"/>
    </visual>
    <inertial>
      <origin rpy="0 0 0" xyz="0.002781 6.3e-05 -0.142518"/>
      <mass value="0.207"/>
      <inertia ixx="0.002129279" ixy="3.9e-08" ixz="5.757e-06" iyy="0.002141463" iyz="-5.16e-07" izz="3.7583e-05"/>
    </inertial>
  </link>

  <link name="RL_foot">
    <visual>
      <origin rpy="0 0 0" xyz="0 0 0"/>
      <geometry>
        <sphere radius="0.0165"/>
      </geometry>
      <material name="green"/>
    </visual>
    <collision>
      <origin rpy="0 0 0" xyz="0 0 0"/>
      <geometry>
        <sphere radius="0.0265"/>
      </geometry>
    </collision>
    <inertial>
      <mass value="0.06"/>
      <inertia ixx="1.6853999999999998e-05" ixy="0.0" ixz="0.0" iyy="1.6853999999999998e-05" iyz="0.0" izz="1.6853999999999998e-05"/>
    </inertial>
  </link>
  
  
  <joint name="FL_hip_joint" type="revolute">
    <origin rpy="0 0 0" xyz="0.049 0.056 -0.0235"/>
    <parent link="trunk1"/>
    <child link="FL_hip"/>
    <axis xyz="1 0 0"/>
    <dynamics damping="0" friction="0"/>
    <limit effort="35.278" lower="-3.1317304763960306" upper="3.1317304763960306" velocity="20"/>
  </joint>
  
  <joint name="FR_hip_joint" type="revolute">
    <origin rpy="0 0 0" xyz="0.049 -0.056 -0.0235"/>
    <parent link="trunk1"/>
    <child link="FR_hip"/>
    <axis xyz="1 0 0"/>
    <dynamics damping="0" friction="0"/>
    <limit effort="35.278" lower="-3.1317304763960306" upper="3.1317304763960306" velocity="20"/>
  </joint>

  <joint name="RL_hip_joint" type="revolute">
    <origin rpy="0 0 0" xyz="-0.049 0.056 -0.0235"/>
    <parent link="trunk6"/>
    <child link="RL_hip"/>
    <axis xyz="1 0 0"/>
    <dynamics damping="0" friction="0"/>
    <limit effort="35.278" lower="-3.1317304763960306" upper="3.1317304763960306" velocity="20"/>
  </joint>

  <joint name="RR_hip_joint" type="revolute">
    <origin rpy="0 0 0" xyz="-0.049 -0.056 -0.0235"/>
    <parent link="trunk6"/>
    <child link="RR_hip"/>
    <axis xyz="1 0 0"/>
    <dynamics damping="0" friction="0"/>
    <limit effort="35.278" lower="-3.1317304763960306" upper="3.1317304763960306" velocity="20"/>
  </joint>

  <joint name="FL_thigh_joint" type="revolute">
    <origin rpy="0 0 0" xyz="0 0.057083 0"/>
    <parent link="FL_hip"/>
    <child link="FL_thigh"/>
    <axis xyz="0 1 0"/>
    <dynamics damping="0" friction="0"/>
    <limit effort="35.278" lower="-3.1317304763960306" upper="3.1317304763960306" velocity="20"/>
  </joint>

  <joint name="FR_thigh_joint" type="revolute">
    <origin rpy="0 0 0" xyz="0 -0.057083 0"/>
    <parent link="FR_hip"/>
    <child link="FR_thigh"/>
    <axis xyz="0 1 0"/>
    <dynamics damping="0" friction="0"/>
    <limit effort="35.278" lower="-3.1317304763960306" upper="3.1317304763960306" velocity="20"/>
  </joint>

  <joint name="RL_thigh_joint" type="revolute">
    <origin rpy="0 0 0" xyz="0 0.057083 0"/>
    <parent link="RL_hip"/>
    <child link="RL_thigh"/>
    <axis xyz="0 1 0"/>
    <dynamics damping="0" friction="0"/>
    <limit effort="35.278" lower="-3.1317304763960306" upper="3.1317304763960306" velocity="20"/>
  </joint>

  <joint name="RR_thigh_joint" type="revolute">
    <origin rpy="0 0 0" xyz="0 -0.057083 0"/>
    <parent link="RR_hip"/>
    <child link="RR_thigh"/>
    <axis xyz="0 1 0"/>
    <dynamics damping="0" friction="0"/>
    <limit effort="35.278" lower="-3.1317304763960306" upper="3.1317304763960306" velocity="20"/>
  </joint>
 
  <joint name="FL_calf_joint" type="revolute">
    <origin rpy="0 0 0" xyz="0 0 -0.25"/>
    <parent link="FL_thigh"/>
    <child link="FL_calf"/>
    <axis xyz="0 1 0"/>
    <dynamics damping="0" friction="0"/>
    <limit effort="35.278" lower="-3.1317304763960306" upper="3.1317304763960306" velocity="20"/>
  </joint> 

  <joint name="FR_calf_joint" type="revolute">
    <origin rpy="0 0 0" xyz="0 0 -0.25"/>
    <parent link="FR_thigh"/>
    <child link="FR_calf"/>
    <axis xyz="0 1 0"/>
    <dynamics damping="0" friction="0"/>
    <limit effort="35.278" lower="-3.1317304763960306" upper="3.1317304763960306" velocity="20"/>
  </joint>
  
  <joint name="RL_calf_joint" type="revolute">
    <origin rpy="0 0 0" xyz="0 0 -0.25"/>
    <parent link="RL_thigh"/>
    <child link="RL_calf"/>
    <axis xyz="0 1 0"/>
    <dynamics damping="0" friction="0"/>
    <limit effort="35.278" lower="-3.1317304763960306" upper="3.1317304763960306" velocity="20"/>
  </joint>

  <joint name="RR_calf_joint" type="revolute">
    <origin rpy="0 0 0" xyz="0 0 -0.25"/>
    <parent link="RR_thigh"/>
    <child link="RR_calf"/>
    <axis xyz="0 1 0"/>
    <dynamics damping="0" friction="0"/>
    <limit effort="35.278" lower="-3.1317304763960306" upper="3.1317304763960306" velocity="20"/>
  </joint>

  <joint name="FL_foot_fixed" type="fixed" dont_collapse="true">
    <origin rpy="0 0 0" xyz="0 0 -0.25"/>
    <parent link="FL_calf"/>
    <child link="FL_foot"/>
  </joint>

  <joint name="FR_foot_fixed" type="fixed" dont_collapse="true">
    <origin rpy="0 0 0" xyz="0 0 -0.25"/>
    <parent link="FR_calf"/>
    <child link="FR_foot"/>
  </joint>

  <joint name="RL_foot_fixed" type="fixed" dont_collapse="true">
    <origin rpy="0 0 0" xyz="0 0 -0.25"/>
    <parent link="RL_calf"/>
    <child link="RL_foot"/>
  </joint>
  
  <joint name="RR_foot_fixed" type="fixed" dont_collapse="true">
    <origin rpy="0 0 0" xyz="0 0 -0.25"/>
    <parent link="RR_calf"/>
    <child link="RR_foot"/>
  </joint>

</robot>

