<robot name="quadruped_robot" xmlns:xacro="http://www.ros.org/wiki/xacro">
  <link name="base"> 
    <visual>
       <origin rpy="0 0 0"  xyz="0 0 0"/>
       <geometry>
           <box size="0.01 0.01 0.01"/>
       </geometry>
    </visual> 
    <collision> 
       <origin rpy="0 0 0" xyz="0 0 0"/>
       <geometry>
           <box size="0.01 0.01 0.01"/>
       </geometry>
    </collision> 
    <inertial> 
       <origin rpy="0 0 0" xyz="0.0 0.0 -0.005685819981630294"/>
       <mass value="7.203394176650595e-07"/>
       <inertia ixx="1.4830074639166873e-11" ixy="0" ixz="0" iyy="1.4830074639166873e-11" iyz="0" izz="1.2005656961084328e-11"/>
    </inertial> 
  </link>

  <link name="trunk"> 
    <visual>
       <origin rpy="0 0 0"  xyz="0 0 0"/>
       <geometry>
           <box size="0.40175108862981995 0.3487281877784439 0.09261811554700795"/>
       </geometry>
    </visual> 
    <collision> 
       <origin rpy="0 0 0" xyz="0 0 0"/>
       <geometry>
           <box size="0.40175108862981995 0.3487281877784439 0.09261811554700795"/>
       </geometry>
    </collision> 
    <inertial> 
       <origin rpy="0 0 0" xyz="0.0 0.0 -0.05266099320381212"/>
       <mass value="0.014493089404382023"/>
       <inertia ixx="0.00016211195839327318" ixy="0" ixz="0" iyy="0.00016211195839327318" iyz="0" izz="0.0003418138204348001"/>
    </inertial> 
  </link>

  <link name="FR_hip"> 
    <visual>
       <origin rpy="0 0 0"  xyz="0 0 0"/>
       <geometry>
           <sphere radius="0.045178046813038"/>
       </geometry>
    </visual> 
    <collision> 
       <origin rpy="0 0 0" xyz="0 0 0"/>
       <geometry>
           <sphere radius="0.045178046813038"/>
       </geometry>
    </collision> 
    <inertial> 
       <origin rpy="0 0 0" xyz="0.0 0.0 0.045178046813038"/>
       <mass value="0.0007133946346302859"/>
       <inertia ixx="5.824313351658488e-07" ixy="0" ixz="0" iyy="5.824313351658488e-07" iyz="0" izz="5.824313351658488e-07"/>
    </inertial> 
  </link>

  <link name="FR_thigh"> 
    <visual>
       <origin rpy="0 0 0"  xyz="0 0 -0.16558785845285673"/>
       <geometry>
           <cylinder length= "0.33117571690571346" radius="0.045178046813038"/>
       </geometry>
    </visual> 
    <collision> 
       <origin rpy="0 0 0" xyz="0 0 -0.16558785845285673"/>
       <geometry>
           <cylinder length= "0.33117571690571346" radius="0.045178046813038"/>
       </geometry>
    </collision> 
    <inertial> 
       <origin rpy="0 0 0" xyz="0.0 0.0 -0.18830055086132433"/>
       <mass value="0.002595583183064086"/>
       <inertia ixx="2.4601166171620643e-05" ixy="0" ixz="0" iyy="2.4601166171620643e-05" iyz="0" izz="2.6488652028296683e-06"/>
    </inertial> 
  </link>

  <link name="FR_knee"> 
    <visual>
       <origin rpy="0 0 0"  xyz="0 0 0"/>
       <geometry>
           <sphere radius="0.045178046813038"/>
       </geometry>
    </visual> 
    <collision> 
       <origin rpy="0 0 0" xyz="0 0 0"/>
       <geometry>
           <sphere radius="0.045178046813038"/>
       </geometry>
    </collision> 
    <inertial> 
       <origin rpy="0 0 0" xyz="0.0 0.0 0.045178046813038"/>
       <mass value="0.0005897571161158912"/>
       <inertia ixx="4.814908998312737e-07" ixy="0" ixz="0" iyy="4.814908998312737e-07" iyz="0" izz="4.814908998312737e-07"/>
    </inertial> 
  </link>

  <link name="FR_calf"> 
    <visual>
       <origin rpy="0 0 0"  xyz="0 0 -0.14127846519187032"/>
       <geometry>
           <cylinder length= "0.28255693038374063" radius="0.043181899178432334"/>
       </geometry>
    </visual> 
    <collision> 
       <origin rpy="0 0 0" xyz="0 0 -0.14127846519187032"/>
       <geometry>
           <cylinder length= "0.28255693038374063" radius="0.043181899178432334"/>
       </geometry>
    </collision> 
    <inertial> 
       <origin rpy="0 0 0" xyz="0.0 0.0 -0.16065678407239925"/>
       <mass value="0.0021896533585434724"/>
       <inertia ixx="1.5314868262840965e-05" ixy="0" ixz="0" iyy="1.5314868262840965e-05" iyz="0" izz="2.041497489164132e-06"/>
    </inertial> 
  </link>

  <link name="FR_foot"> 
    <visual>
       <origin rpy="0 0 0"  xyz="0 0 0"/>
       <geometry>
           <sphere radius="0.03022732942490263"/>
       </geometry>
    </visual> 
    <collision> 
       <origin rpy="0 0 0" xyz="0 0 0"/>
       <geometry>
           <sphere radius="0.03022732942490263"/>
       </geometry>
    </collision> 
    <inertial> 
       <origin rpy="0 0 0" xyz="0.0 0.0 0.03022732942490263"/>
       <mass value="0.0002211679474225979"/>
       <inertia ixx="8.083170451312274e-08" ixy="0" ixz="0" iyy="8.083170451312274e-08" iyz="0" izz="8.083170451312274e-08"/>
    </inertial> 
  </link>

  <link name="FL_hip"> 
    <visual>
       <origin rpy="0 0 0"  xyz="0 0 0"/>
       <geometry>
           <sphere radius="0.045178046813038"/>
       </geometry>
    </visual> 
    <collision> 
       <origin rpy="0 0 0" xyz="0 0 0"/>
       <geometry>
           <sphere radius="0.045178046813038"/>
       </geometry>
    </collision> 
    <inertial> 
       <origin rpy="0 0 0" xyz="0.0 0.0 0.045178046813038"/>
       <mass value="0.00022932322639885932"/>
       <inertia ixx="1.87224610969001e-07" ixy="0" ixz="0" iyy="1.87224610969001e-07" iyz="0" izz="1.87224610969001e-07"/>
    </inertial> 
  </link>

  <link name="FL_thigh"> 
    <visual>
       <origin rpy="0 0 0"  xyz="0 0 -0.16558785845285673"/>
       <geometry>
           <cylinder length= "0.33117571690571346" radius="0.045178046813038"/>
       </geometry>
    </visual> 
    <collision> 
       <origin rpy="0 0 0" xyz="0 0 -0.16558785845285673"/>
       <geometry>
           <cylinder length= "0.33117571690571346" radius="0.045178046813038"/>
       </geometry>
    </collision> 
    <inertial> 
       <origin rpy="0 0 0" xyz="0.0 0.0 -0.18830055086132433"/>
       <mass value="0.0035319234883072845"/>
       <inertia ixx="3.3475882109362626e-05" ixy="0" ixz="0" iyy="3.3475882109362626e-05" iyz="0" izz="3.6044266615218513e-06"/>
    </inertial> 
  </link>

  <link name="FL_knee"> 
    <visual>
       <origin rpy="0 0 0"  xyz="0 0 0"/>
       <geometry>
           <sphere radius="0.045178046813038"/>
       </geometry>
    </visual> 
    <collision> 
       <origin rpy="0 0 0" xyz="0 0 0"/>
       <geometry>
           <sphere radius="0.045178046813038"/>
       </geometry>
    </collision> 
    <inertial> 
       <origin rpy="0 0 0" xyz="0.0 0.0 0.045178046813038"/>
       <mass value="0.0004655652060141283"/>
       <inertia ixx="3.800978468055059e-07" ixy="0" ixz="0" iyy="3.800978468055059e-07" iyz="0" izz="3.800978468055059e-07"/>
    </inertial> 
  </link>

  <link name="FL_calf"> 
    <visual>
       <origin rpy="0 0 0"  xyz="0 0 -0.14127846519187032"/>
       <geometry>
           <cylinder length= "0.28255693038374063" radius="0.043181899178432334"/>
       </geometry>
    </visual> 
    <collision> 
       <origin rpy="0 0 0" xyz="0 0 -0.14127846519187032"/>
       <geometry>
           <cylinder length= "0.28255693038374063" radius="0.043181899178432334"/>
       </geometry>
    </collision> 
    <inertial> 
       <origin rpy="0 0 0" xyz="0.0 0.0 -0.16065678407239925"/>
       <mass value="0.0021743238101132596"/>
       <inertia ixx="1.52076503720175e-05" ixy="0" ixz="0" iyy="1.52076503720175e-05" iyz="0" izz="2.027205165446228e-06"/>
    </inertial> 
  </link>

  <link name="FL_foot"> 
    <visual>
       <origin rpy="0 0 0"  xyz="0 0 0"/>
       <geometry>
           <sphere radius="0.03022732942490263"/>
       </geometry>
    </visual> 
    <collision> 
       <origin rpy="0 0 0" xyz="0 0 0"/>
       <geometry>
           <sphere radius="0.03022732942490263"/>
       </geometry>
    </collision> 
    <inertial> 
       <origin rpy="0 0 0" xyz="0.0 0.0 0.03022732942490263"/>
       <mass value="0.00018492113189266972"/>
       <inertia ixx="6.758434242200329e-08" ixy="0" ixz="0" iyy="6.758434242200329e-08" iyz="0" izz="6.758434242200329e-08"/>
    </inertial> 
  </link>

  <link name="RR_hip"> 
    <visual>
       <origin rpy="0 0 0"  xyz="0 0 0"/>
       <geometry>
           <sphere radius="0.045178046813038"/>
       </geometry>
    </visual> 
    <collision> 
       <origin rpy="0 0 0" xyz="0 0 0"/>
       <geometry>
           <sphere radius="0.045178046813038"/>
       </geometry>
    </collision> 
    <inertial> 
       <origin rpy="0 0 0" xyz="0.0 0.0 0.045178046813038"/>
       <mass value="0.0006461741726299969"/>
       <inertia ixx="5.275510465671217e-07" ixy="0" ixz="0" iyy="5.275510465671217e-07" iyz="0" izz="5.275510465671217e-07"/>
    </inertial> 
  </link>

  <link name="RR_thigh"> 
    <visual>
       <origin rpy="0 0 0"  xyz="0 0 -0.16558785845285673"/>
       <geometry>
           <cylinder length= "0.33117571690571346" radius="0.045178046813038"/>
       </geometry>
    </visual> 
    <collision> 
       <origin rpy="0 0 0" xyz="0 0 -0.16558785845285673"/>
       <geometry>
           <cylinder length= "0.33117571690571346" radius="0.045178046813038"/>
       </geometry>
    </collision> 
    <inertial> 
       <origin rpy="0 0 0" xyz="0.0 0.0 -0.18830055086132433"/>
       <mass value="0.001527485349278443"/>
       <inertia ixx="1.4477640765862198e-05" ixy="0" ixz="0" iyy="1.4477640765862198e-05" iyz="0" izz="1.558841502725166e-06"/>
    </inertial> 
  </link>

  <link name="RR_knee"> 
    <visual>
       <origin rpy="0 0 0"  xyz="0 0 0"/>
       <geometry>
           <sphere radius="0.045178046813038"/>
       </geometry>
    </visual> 
    <collision> 
       <origin rpy="0 0 0" xyz="0 0 0"/>
       <geometry>
           <sphere radius="0.045178046813038"/>
       </geometry>
    </collision> 
    <inertial> 
       <origin rpy="0 0 0" xyz="0.0 0.0 0.045178046813038"/>
       <mass value="0.0006060964622261971"/>
       <inertia ixx="4.948307074339679e-07" ixy="0" ixz="0" iyy="4.948307074339679e-07" iyz="0" izz="4.948307074339679e-07"/>
    </inertial> 
  </link>

  <link name="RR_calf"> 
    <visual>
       <origin rpy="0 0 0"  xyz="0 0 -0.14127846519187032"/>
       <geometry>
           <cylinder length= "0.28255693038374063" radius="0.043181899178432334"/>
       </geometry>
    </visual> 
    <collision> 
       <origin rpy="0 0 0" xyz="0 0 -0.14127846519187032"/>
       <geometry>
           <cylinder length= "0.28255693038374063" radius="0.043181899178432334"/>
       </geometry>
    </collision> 
    <inertial> 
       <origin rpy="0 0 0" xyz="0.0 0.0 -0.16065678407239925"/>
       <mass value="0.002988473888183745"/>
       <inertia ixx="2.090197689323688e-05" ixy="0" ixz="0" iyy="2.090197689323688e-05" iyz="0" izz="2.786268390544686e-06"/>
    </inertial> 
  </link>

  <link name="RR_foot"> 
    <visual>
       <origin rpy="0 0 0"  xyz="0 0 0"/>
       <geometry>
           <sphere radius="0.03022732942490263"/>
       </geometry>
    </visual> 
    <collision> 
       <origin rpy="0 0 0" xyz="0 0 0"/>
       <geometry>
           <sphere radius="0.03022732942490263"/>
       </geometry>
    </collision> 
    <inertial> 
       <origin rpy="0 0 0" xyz="0.0 0.0 0.03022732942490263"/>
       <mass value="0.00010220979717657491"/>
       <inertia ixx="3.7355286875890954e-08" ixy="0" ixz="0" iyy="3.7355286875890954e-08" iyz="0" izz="3.7355286875890954e-08"/>
    </inertial> 
  </link>

  <link name="RL_hip"> 
    <visual>
       <origin rpy="0 0 0"  xyz="0 0 0"/>
       <geometry>
           <sphere radius="0.045178046813038"/>
       </geometry>
    </visual> 
    <collision> 
       <origin rpy="0 0 0" xyz="0 0 0"/>
       <geometry>
           <sphere radius="0.045178046813038"/>
       </geometry>
    </collision> 
    <inertial> 
       <origin rpy="0 0 0" xyz="0.0 0.0 0.045178046813038"/>
       <mass value="0.0002645088064979321"/>
       <inertia ixx="2.1595090550625722e-07" ixy="0" ixz="0" iyy="2.1595090550625722e-07" iyz="0" izz="2.1595090550625722e-07"/>
    </inertial> 
  </link>

  <link name="RL_thigh"> 
    <visual>
       <origin rpy="0 0 0"  xyz="0 0 -0.16558785845285673"/>
       <geometry>
           <cylinder length= "0.33117571690571346" radius="0.045178046813038"/>
       </geometry>
    </visual> 
    <collision> 
       <origin rpy="0 0 0" xyz="0 0 -0.16558785845285673"/>
       <geometry>
           <cylinder length= "0.33117571690571346" radius="0.045178046813038"/>
       </geometry>
    </collision> 
    <inertial> 
       <origin rpy="0 0 0" xyz="0.0 0.0 -0.18830055086132433"/>
       <mass value="0.0039907554860377815"/>
       <inertia ixx="3.782473222315454e-05" ixy="0" ixz="0" iyy="3.782473222315454e-05" iyz="0" izz="4.072677542735519e-06"/>
    </inertial> 
  </link>

  <link name="RL_knee"> 
    <visual>
       <origin rpy="0 0 0"  xyz="0 0 0"/>
       <geometry>
           <sphere radius="0.045178046813038"/>
       </geometry>
    </visual> 
    <collision> 
       <origin rpy="0 0 0" xyz="0 0 0"/>
       <geometry>
           <sphere radius="0.045178046813038"/>
       </geometry>
    </collision> 
    <inertial> 
       <origin rpy="0 0 0" xyz="0.0 0.0 0.045178046813038"/>
       <mass value="0.0007413487391799301"/>
       <inertia ixx="6.052536913287218e-07" ixy="0" ixz="0" iyy="6.052536913287218e-07" iyz="0" izz="6.052536913287218e-07"/>
    </inertial> 
  </link>

  <link name="RL_calf"> 
    <visual>
       <origin rpy="0 0 0"  xyz="0 0 -0.14127846519187032"/>
       <geometry>
           <cylinder length= "0.28255693038374063" radius="0.043181899178432334"/>
       </geometry>
    </visual> 
    <collision> 
       <origin rpy="0 0 0" xyz="0 0 -0.14127846519187032"/>
       <geometry>
           <cylinder length= "0.28255693038374063" radius="0.043181899178432334"/>
       </geometry>
    </collision> 
    <inertial> 
       <origin rpy="0 0 0" xyz="0.0 0.0 -0.16065678407239925"/>
       <mass value="0.0012361981975151917"/>
       <inertia ixx="8.646214464877704e-06" ixy="0" ixz="0" iyy="8.646214464877704e-06" iyz="0" izz="1.1525548126097993e-06"/>
    </inertial> 
  </link>

  <link name="RL_foot"> 
    <visual>
       <origin rpy="0 0 0"  xyz="0 0 0"/>
       <geometry>
           <sphere radius="0.03022732942490263"/>
       </geometry>
    </visual> 
    <collision> 
       <origin rpy="0 0 0" xyz="0 0 0"/>
       <geometry>
           <sphere radius="0.03022732942490263"/>
       </geometry>
    </collision> 
    <inertial> 
       <origin rpy="0 0 0" xyz="0.0 0.0 0.03022732942490263"/>
       <mass value="0.0001796348284367131"/>
       <inertia ixx="6.565232232642354e-08" ixy="0" ixz="0" iyy="6.565232232642354e-08" iyz="0" izz="6.565232232642354e-08"/>
    </inertial> 
  </link>

  <joint name="floating_base" type="fixed" dont_collapse="true">
    <origin rpy="0 0 0"  xyz="0 0 0"/>
    <parent link="base"/>
    <child link="trunk"/>
  </joint>

  <joint name="FR_hip_joint" type="revolute">
    <origin rpy="0 0 0"  xyz="0.20087554431490998 -0.17436409388922194 -0.03704724621880318"/>
    <parent link="trunk"/>
    <child link="FR_hip"/>
    <axis xyz="1 0 0"/>
    <dynamics damping="0" friction="0"/>
    <limit effort="60" lower="-3.141592653" upper="3.141592653" velocity="52.4"/>
  </joint>

  <joint name="FR_thigh_joint" type="revolute">
    <origin rpy="0 0 0"  xyz="0 0 0"/>
    <parent link="FR_hip"/>
    <child link="FR_thigh"/>
    <axis xyz="0 1 0"/>
    <dynamics damping="0" friction="0"/>
    <limit effort="60" lower="-3.141592653" upper="3.141592653" velocity="52.4"/>
  </joint>

  <joint name="FR_knee_joint" type="fixed" dont_collapse="true">
    <origin rpy="0 0 0"  xyz="0 0 -0.33117571690571346"/>
    <parent link="FR_thigh"/>
    <child link="FR_knee"/>
  </joint>

  <joint name="FR_calf_joint" type="revolute">
    <origin rpy="0 0 0"  xyz="0 0 0"/>
    <parent link="FR_knee"/>
    <child link="FR_calf"/>
    <axis xyz="0 1 0"/>
    <dynamics damping="0" friction="0"/>
    <limit effort="60" lower="-3.141592653" upper="3.141592653" velocity="52.4"/>
  </joint>

  <joint name="FR_foot_joint" type="fixed" dont_collapse="true">
    <origin rpy="0 0 0"  xyz="0 0 -0.28255693038374063"/>
    <parent link="FR_calf"/>
    <child link="FR_foot"/>
  </joint>

  <joint name="FL_hip_joint" type="revolute">
    <origin rpy="0 0 0"  xyz="0.20087554431490998 0.17436409388922194 -0.03704724621880318"/>
    <parent link="trunk"/>
    <child link="FL_hip"/>
    <axis xyz="1 0 0"/>
    <dynamics damping="0" friction="0"/>
    <limit effort="60" lower="-3.141592653" upper="3.141592653" velocity="52.4"/>
  </joint>

  <joint name="FL_thigh_joint" type="revolute">
    <origin rpy="0 0 0"  xyz="0 0 0"/>
    <parent link="FL_hip"/>
    <child link="FL_thigh"/>
    <axis xyz="0 1 0"/>
    <dynamics damping="0" friction="0"/>
    <limit effort="60" lower="-3.141592653" upper="3.141592653" velocity="52.4"/>
  </joint>

  <joint name="FL_knee_joint" type="fixed" dont_collapse="true">
    <origin rpy="0 0 0"  xyz="0 0 -0.33117571690571346"/>
    <parent link="FL_thigh"/>
    <child link="FL_knee"/>
  </joint>

  <joint name="FL_calf_joint" type="revolute">
    <origin rpy="0 0 0"  xyz="0 0 0"/>
    <parent link="FL_knee"/>
    <child link="FL_calf"/>
    <axis xyz="0 1 0"/>
    <dynamics damping="0" friction="0"/>
    <limit effort="60" lower="-3.141592653" upper="3.141592653" velocity="52.4"/>
  </joint>

  <joint name="FL_foot_joint" type="fixed" dont_collapse="true">
    <origin rpy="0 0 0"  xyz="0 0 -0.28255693038374063"/>
    <parent link="FL_calf"/>
    <child link="FL_foot"/>
  </joint>

  <joint name="RR_hip_joint" type="revolute">
    <origin rpy="0 0 0"  xyz="-0.20087554431490998 -0.17436409388922194 -0.03704724621880318"/>
    <parent link="trunk"/>
    <child link="RR_hip"/>
    <axis xyz="1 0 0"/>
    <dynamics damping="0" friction="0"/>
    <limit effort="60" lower="-3.141592653" upper="3.141592653" velocity="52.4"/>
  </joint>

  <joint name="RR_thigh_joint" type="revolute">
    <origin rpy="0 0 0"  xyz="0 0 0"/>
    <parent link="RR_hip"/>
    <child link="RR_thigh"/>
    <axis xyz="0 1 0"/>
    <dynamics damping="0" friction="0"/>
    <limit effort="60" lower="-3.141592653" upper="3.141592653" velocity="52.4"/>
  </joint>

  <joint name="RR_knee_joint" type="fixed" dont_collapse="true">
    <origin rpy="0 0 0"  xyz="0 0 -0.33117571690571346"/>
    <parent link="RR_thigh"/>
    <child link="RR_knee"/>
  </joint>

  <joint name="RR_calf_joint" type="revolute">
    <origin rpy="0 0 0"  xyz="0 0 0"/>
    <parent link="RR_knee"/>
    <child link="RR_calf"/>
    <axis xyz="0 1 0"/>
    <dynamics damping="0" friction="0"/>
    <limit effort="60" lower="-3.141592653" upper="3.141592653" velocity="52.4"/>
  </joint>

  <joint name="RR_foot_joint" type="fixed" dont_collapse="true">
    <origin rpy="0 0 0"  xyz="0 0 -0.28255693038374063"/>
    <parent link="RR_calf"/>
    <child link="RR_foot"/>
  </joint>

  <joint name="RL_hip_joint" type="revolute">
    <origin rpy="0 0 0"  xyz="-0.20087554431490998 0.17436409388922194 -0.03704724621880318"/>
    <parent link="trunk"/>
    <child link="RL_hip"/>
    <axis xyz="1 0 0"/>
    <dynamics damping="0" friction="0"/>
    <limit effort="60" lower="-3.141592653" upper="3.141592653" velocity="52.4"/>
  </joint>

  <joint name="RL_thigh_joint" type="revolute">
    <origin rpy="0 0 0"  xyz="0 0 0"/>
    <parent link="RL_hip"/>
    <child link="RL_thigh"/>
    <axis xyz="0 1 0"/>
    <dynamics damping="0" friction="0"/>
    <limit effort="60" lower="-3.141592653" upper="3.141592653" velocity="52.4"/>
  </joint>

  <joint name="RL_knee_joint" type="fixed" dont_collapse="true">
    <origin rpy="0 0 0"  xyz="0 0 -0.33117571690571346"/>
    <parent link="RL_thigh"/>
    <child link="RL_knee"/>
  </joint>

  <joint name="RL_calf_joint" type="revolute">
    <origin rpy="0 0 0"  xyz="0 0 0"/>
    <parent link="RL_knee"/>
    <child link="RL_calf"/>
    <axis xyz="0 1 0"/>
    <dynamics damping="0" friction="0"/>
    <limit effort="60" lower="-3.141592653" upper="3.141592653" velocity="52.4"/>
  </joint>

  <joint name="RL_foot_joint" type="fixed" dont_collapse="true">
    <origin rpy="0 0 0"  xyz="0 0 -0.28255693038374063"/>
    <parent link="RL_calf"/>
    <child link="RL_foot"/>
  </joint>

 </robot> 