<robot name="quadruped_robot" xmlns:xacro="http://www.ros.org/wiki/xacro">
  <link name="base"> 
    <visual>
       <origin rpy="0 0 0"  xyz="0 0 0"/>
       <geometry>
           <box size="0.01 0.01 0.01"/>
       </geometry>
    </visual>
  </link>

  <link name="trunk"> 
    <visual>
       <origin rpy="0 0 0"  xyz="0 0 0"/>
       <geometry>
           <box size="0.6861772090809941 0.3034325696406455 0.0954450721288132"/>
       </geometry>
    </visual> 
    <collision> 
       <origin rpy="0 0 0" xyz="0 0 0"/>
       <geometry>
           <box size="0.6861772090809941 0.3034325696406455 0.0954450721288132"/>
       </geometry>
    </collision> 
    <inertial> 
       <origin rpy="0 0 0" xyz="0.0 0.0 -0.0477225360644066"/>
       <mass value="29.808714923389527"/>
       <inertia ixx="0.25133984596362047" ixy="0" ixz="0" iyy="0.25133984596362047" iyz="0" izz="1.3983031851563965"/>
    </inertial> 
  </link>

  <link name="FR_hip"> 
    <visual>
       <origin rpy="0 0 0"  xyz="0 0 0"/>
       <geometry>
           <sphere radius="0.04137735453050819"/>
       </geometry>
    </visual> 
    <!-- <collision> 
       <origin rpy="0 0 0" xyz="0 0 0"/>
       <geometry>
           <sphere radius="0.04137735453050819"/>
       </geometry>
    </collision>  -->
    <inertial> 
       <origin rpy="0 0 0" xyz="0.0 0.0 0.04137735453050819"/>
       <mass value="0.4451106953851888"/>
       <inertia ixx="0.00030482702127805937" ixy="0" ixz="0" iyy="0.00030482702127805937" iyz="0" izz="0.00030482702127805937"/>
    </inertial> 
  </link>

  <link name="FR_thigh"> 
    <visual>
       <origin rpy="0 0 0"  xyz="0 0 -0.16301713389930214"/>
       <geometry>
           <cylinder length= "0.3260342677986043" radius="0.04137735453050819"/>
       </geometry>
    </visual> 
    <!-- <collision> 
       <origin rpy="0 0 0" xyz="0 0 -0.16301713389930214"/>
       <geometry>
           <cylinder length= "0.3260342677986043" radius="0.04137735453050819"/>
       </geometry>
    </collision>  -->
    <inertial> 
       <origin rpy="0 0 0" xyz="0.0 0.0 -0.16301713389930214"/>
       <mass value="2.6304486108259537"/>
       <inertia ixx="0.024426915770733117" ixy="0" ixz="0" iyy="0.024426915770733117" iyz="0" izz="0.002251776420383466"/>
    </inertial> 
  </link>

  <link name="FR_knee"> 
    <visual>
       <origin rpy="0 0 0"  xyz="0 0 0"/>
       <geometry>
           <sphere radius="0.0429619227247509"/>
       </geometry>
    </visual> 
    <!-- <collision> 
       <origin rpy="0 0 0" xyz="0 0 0"/>
       <geometry>
           <sphere radius="0.0429619227247509"/>
       </geometry>
    </collision>  -->
    <inertial> 
       <origin rpy="0 0 0" xyz="0.0 0.0 0.0429619227247509"/>
       <mass value="0.4982312882835031"/>
       <inertia ixx="0.0003678395373918719" ixy="0" ixz="0" iyy="0.0003678395373918719" iyz="0" izz="0.0003678395373918719"/>
    </inertial> 
  </link>

  <link name="FR_calf"> 
    <visual>
       <origin rpy="0 0 0"  xyz="0 0 -0.13376101745186045"/>
       <geometry>
           <cylinder length= "0.2675220349037209" radius="0.0429619227247509"/>
       </geometry>
    </visual> 
    <!-- <collision> 
       <origin rpy="0 0 0" xyz="0 0 -0.13376101745186045"/>
       <geometry>
           <cylinder length= "0.2675220349037209" radius="0.0429619227247509"/>
       </geometry>
    </collision>  -->
    <inertial> 
       <origin rpy="0 0 0" xyz="0.0 0.0 -0.13376101745186045"/>
       <mass value="2.3268485144669113"/>
       <inertia ixx="0.014951013801494913" ixy="0" ixz="0" iyy="0.014951013801494913" iyz="0" izz="0.002147363336240953"/>
    </inertial> 
  </link>

  <link name="FR_foot"> 
    <visual>
       <origin rpy="0 0 0"  xyz="0 0 0"/>
       <geometry>
           <sphere radius="0.02896414817135573"/>
       </geometry>
    </visual> 
    <collision> 
       <origin rpy="0 0 0" xyz="0 0 0"/>
       <geometry>
           <sphere radius="0.02896414817135573"/>
       </geometry>
    </collision> 
    <inertial> 
       <origin rpy="0 0 0" xyz="0.0 0.0 0.02896414817135573"/>
       <mass value="0.15267296851711973"/>
       <inertia ixx="5.1232277466203415e-05" ixy="0" ixz="0" iyy="5.1232277466203415e-05" iyz="0" izz="5.1232277466203415e-05"/>
    </inertial> 
  </link>

  <link name="FL_hip"> 
    <visual>
       <origin rpy="0 0 0"  xyz="0 0 0"/>
       <geometry>
           <sphere radius="0.04137735453050819"/>
       </geometry>
    </visual> 
    <!-- <collision> 
       <origin rpy="0 0 0" xyz="0 0 0"/>
       <geometry>
           <sphere radius="0.04137735453050819"/>
       </geometry>
    </collision>  -->
    <inertial> 
       <origin rpy="0 0 0" xyz="0.0 0.0 0.04137735453050819"/>
       <mass value="0.4451106953851888"/>
       <inertia ixx="0.00030482702127805937" ixy="0" ixz="0" iyy="0.00030482702127805937" iyz="0" izz="0.00030482702127805937"/>
    </inertial> 
  </link>

  <link name="FL_thigh"> 
    <visual>
       <origin rpy="0 0 0"  xyz="0 0 -0.16301713389930214"/>
       <geometry>
           <cylinder length= "0.3260342677986043" radius="0.04137735453050819"/>
       </geometry>
    </visual> 
    <!-- <collision> 
       <origin rpy="0 0 0" xyz="0 0 -0.16301713389930214"/>
       <geometry>
           <cylinder length= "0.3260342677986043" radius="0.04137735453050819"/>
       </geometry>
    </collision>  -->
    <inertial> 
       <origin rpy="0 0 0" xyz="0.0 0.0 -0.16301713389930214"/>
       <mass value="2.6304486108259537"/>
       <inertia ixx="0.024426915770733117" ixy="0" ixz="0" iyy="0.024426915770733117" iyz="0" izz="0.002251776420383466"/>
    </inertial> 
  </link>

  <link name="FL_knee"> 
    <visual>
       <origin rpy="0 0 0"  xyz="0 0 0"/>
       <geometry>
           <sphere radius="0.0429619227247509"/>
       </geometry>
    </visual> 
    <!-- <collision> 
       <origin rpy="0 0 0" xyz="0 0 0"/>
       <geometry>
           <sphere radius="0.0429619227247509"/>
       </geometry>
    </collision>  -->
    <inertial> 
       <origin rpy="0 0 0" xyz="0.0 0.0 0.0429619227247509"/>
       <mass value="0.4982312882835031"/>
       <inertia ixx="0.0003678395373918719" ixy="0" ixz="0" iyy="0.0003678395373918719" iyz="0" izz="0.0003678395373918719"/>
    </inertial> 
  </link>

  <link name="FL_calf"> 
    <visual>
       <origin rpy="0 0 0"  xyz="0 0 -0.13376101745186045"/>
       <geometry>
           <cylinder length= "0.2675220349037209" radius="0.0429619227247509"/>
       </geometry>
    </visual> 
    <!-- <collision> 
       <origin rpy="0 0 0" xyz="0 0 -0.13376101745186045"/>
       <geometry>
           <cylinder length= "0.2675220349037209" radius="0.0429619227247509"/>
       </geometry>
    </collision>  -->
    <inertial> 
       <origin rpy="0 0 0" xyz="0.0 0.0 -0.13376101745186045"/>
       <mass value="2.3268485144669113"/>
       <inertia ixx="0.014951013801494913" ixy="0" ixz="0" iyy="0.014951013801494913" iyz="0" izz="0.002147363336240953"/>
    </inertial> 
  </link>

  <link name="FL_foot"> 
    <visual>
       <origin rpy="0 0 0"  xyz="0 0 0"/>
       <geometry>
           <sphere radius="0.02896414817135573"/>
       </geometry>
    </visual> 
    <collision> 
       <origin rpy="0 0 0" xyz="0 0 0"/>
       <geometry>
           <sphere radius="0.02896414817135573"/>
       </geometry>
    </collision> 
    <inertial> 
       <origin rpy="0 0 0" xyz="0.0 0.0 0.02896414817135573"/>
       <mass value="0.15267296851711973"/>
       <inertia ixx="5.1232277466203415e-05" ixy="0" ixz="0" iyy="5.1232277466203415e-05" iyz="0" izz="5.1232277466203415e-05"/>
    </inertial> 
  </link>

  <link name="RR_hip"> 
    <visual>
       <origin rpy="0 0 0"  xyz="0 0 0"/>
       <geometry>
           <sphere radius="0.04137735453050819"/>
       </geometry>
    </visual> 
    <!-- <collision> 
       <origin rpy="0 0 0" xyz="0 0 0"/>
       <geometry>
           <sphere radius="0.04137735453050819"/>
       </geometry>
    </collision>  -->
    <inertial> 
       <origin rpy="0 0 0" xyz="0.0 0.0 0.04137735453050819"/>
       <mass value="0.4451106953851888"/>
       <inertia ixx="0.00030482702127805937" ixy="0" ixz="0" iyy="0.00030482702127805937" iyz="0" izz="0.00030482702127805937"/>
    </inertial> 
  </link>

  <link name="RR_thigh"> 
    <visual>
       <origin rpy="0 0 0"  xyz="0 0 -0.16301713389930214"/>
       <geometry>
           <cylinder length= "0.3260342677986043" radius="0.04137735453050819"/>
       </geometry>
    </visual> 
    <!-- <collision> 
       <origin rpy="0 0 0" xyz="0 0 -0.16301713389930214"/>
       <geometry>
           <cylinder length= "0.3260342677986043" radius="0.04137735453050819"/>
       </geometry>
    </collision>  -->
    <inertial> 
       <origin rpy="0 0 0" xyz="0.0 0.0 -0.16301713389930214"/>
       <mass value="2.6304486108259537"/>
       <inertia ixx="0.024426915770733117" ixy="0" ixz="0" iyy="0.024426915770733117" iyz="0" izz="0.002251776420383466"/>
    </inertial> 
  </link>

  <link name="RR_knee"> 
    <visual>
       <origin rpy="0 0 0"  xyz="0 0 0"/>
       <geometry>
           <sphere radius="0.0429619227247509"/>
       </geometry>
    </visual> 
    <!-- <collision> 
       <origin rpy="0 0 0" xyz="0 0 0"/>
       <geometry>
           <sphere radius="0.0429619227247509"/>
       </geometry>
    </collision>  -->
    <inertial> 
       <origin rpy="0 0 0" xyz="0.0 0.0 0.0429619227247509"/>
       <mass value="0.4982312882835031"/>
       <inertia ixx="0.0003678395373918719" ixy="0" ixz="0" iyy="0.0003678395373918719" iyz="0" izz="0.0003678395373918719"/>
    </inertial> 
  </link>

  <link name="RR_calf"> 
    <visual>
       <origin rpy="0 0 0"  xyz="0 0 -0.13376101745186045"/>
       <geometry>
           <cylinder length= "0.2675220349037209" radius="0.0429619227247509"/>
       </geometry>
    </visual> 
    <!-- <collision> 
       <origin rpy="0 0 0" xyz="0 0 -0.13376101745186045"/>
       <geometry>
           <cylinder length= "0.2675220349037209" radius="0.0429619227247509"/>
       </geometry>
    </collision>  -->
    <inertial> 
       <origin rpy="0 0 0" xyz="0.0 0.0 -0.13376101745186045"/>
       <mass value="2.3268485144669113"/>
       <inertia ixx="0.014951013801494913" ixy="0" ixz="0" iyy="0.014951013801494913" iyz="0" izz="0.002147363336240953"/>
    </inertial> 
  </link>

  <link name="RR_foot"> 
    <visual>
       <origin rpy="0 0 0"  xyz="0 0 0"/>
       <geometry>
           <sphere radius="0.02896414817135573"/>
       </geometry>
    </visual> 
    <collision> 
       <origin rpy="0 0 0" xyz="0 0 0"/>
       <geometry>
           <sphere radius="0.02896414817135573"/>
       </geometry>
    </collision> 
    <inertial> 
       <origin rpy="0 0 0" xyz="0.0 0.0 0.02896414817135573"/>
       <mass value="0.15267296851711973"/>
       <inertia ixx="5.1232277466203415e-05" ixy="0" ixz="0" iyy="5.1232277466203415e-05" iyz="0" izz="5.1232277466203415e-05"/>
    </inertial> 
  </link>

  <link name="RL_hip"> 
    <visual>
       <origin rpy="0 0 0"  xyz="0 0 0"/>
       <geometry>
           <sphere radius="0.04137735453050819"/>
       </geometry>
    </visual> 
    <!-- <collision> 
       <origin rpy="0 0 0" xyz="0 0 0"/>
       <geometry>
           <sphere radius="0.04137735453050819"/>
       </geometry>
    </collision>  -->
    <inertial> 
       <origin rpy="0 0 0" xyz="0.0 0.0 0.04137735453050819"/>
       <mass value="0.4451106953851888"/>
       <inertia ixx="0.00030482702127805937" ixy="0" ixz="0" iyy="0.00030482702127805937" iyz="0" izz="0.00030482702127805937"/>
    </inertial> 
  </link>

  <link name="RL_thigh"> 
    <visual>
       <origin rpy="0 0 0"  xyz="0 0 -0.16301713389930214"/>
       <geometry>
           <cylinder length= "0.3260342677986043" radius="0.04137735453050819"/>
       </geometry>
    </visual> 
    <!-- <collision> 
       <origin rpy="0 0 0" xyz="0 0 -0.16301713389930214"/>
       <geometry>
           <cylinder length= "0.3260342677986043" radius="0.04137735453050819"/>
       </geometry>
    </collision>  -->
    <inertial> 
       <origin rpy="0 0 0" xyz="0.0 0.0 -0.16301713389930214"/>
       <mass value="2.6304486108259537"/>
       <inertia ixx="0.024426915770733117" ixy="0" ixz="0" iyy="0.024426915770733117" iyz="0" izz="0.002251776420383466"/>
    </inertial> 
  </link>

  <link name="RL_knee"> 
    <visual>
       <origin rpy="0 0 0"  xyz="0 0 0"/>
       <geometry>
           <sphere radius="0.0429619227247509"/>
       </geometry>
    </visual> 
    <!-- <collision> 
       <origin rpy="0 0 0" xyz="0 0 0"/>
       <geometry>
           <sphere radius="0.0429619227247509"/>
       </geometry>
    </collision>  -->
    <inertial> 
       <origin rpy="0 0 0" xyz="0.0 0.0 0.0429619227247509"/>
       <mass value="0.4982312882835031"/>
       <inertia ixx="0.0003678395373918719" ixy="0" ixz="0" iyy="0.0003678395373918719" iyz="0" izz="0.0003678395373918719"/>
    </inertial> 
  </link>

  <link name="RL_calf"> 
    <visual>
       <origin rpy="0 0 0"  xyz="0 0 -0.13376101745186045"/>
       <geometry>
           <cylinder length= "0.2675220349037209" radius="0.0429619227247509"/>
       </geometry>
    </visual> 
    <!-- <collision> 
       <origin rpy="0 0 0" xyz="0 0 -0.13376101745186045"/>
       <geometry>
           <cylinder length= "0.2675220349037209" radius="0.0429619227247509"/>
       </geometry>
    </collision>  -->
    <inertial> 
       <origin rpy="0 0 0" xyz="0.0 0.0 -0.13376101745186045"/>
       <mass value="2.3268485144669113"/>
       <inertia ixx="0.014951013801494913" ixy="0" ixz="0" iyy="0.014951013801494913" iyz="0" izz="0.002147363336240953"/>
    </inertial> 
  </link>

  <link name="RL_foot"> 
    <visual>
       <origin rpy="0 0 0"  xyz="0 0 0"/>
       <geometry>
           <sphere radius="0.02896414817135573"/>
       </geometry>
    </visual> 
    <collision> 
       <origin rpy="0 0 0" xyz="0 0 0"/>
       <geometry>
           <sphere radius="0.02896414817135573"/>
       </geometry>
    </collision> 
    <inertial> 
       <origin rpy="0 0 0" xyz="0.0 0.0 0.02896414817135573"/>
       <mass value="0.15267296851711973"/>
       <inertia ixx="5.1232277466203415e-05" ixy="0" ixz="0" iyy="5.1232277466203415e-05" iyz="0" izz="5.1232277466203415e-05"/>
    </inertial> 
  </link>

  <joint name="floating_base" type="fixed" dont_collapse="true">
    <origin rpy="0 0 0"  xyz="0 0 0"/>
    <parent link="base"/>
    <child link="trunk"/>
  </joint>

  <joint name="FR_hip_joint" type="revolute">
    <origin rpy="0 0 0"  xyz="0.34308860454049706 -0.15171628482032276 -0.038178028851525284"/>
    <parent link="trunk"/>
    <child link="FR_hip"/>
    <axis xyz="1 0 0"/>
    <dynamics damping="0" friction="0"/>
    <limit effort="60" lower="-3.141592653" upper="3.141592653" velocity="52.4"/>
  </joint>

  <joint name="FR_thigh_joint" type="revolute">
    <origin rpy="0 0 0"  xyz="0 0 0"/>
    <parent link="FR_hip"/>
    <child link="FR_thigh"/>
    <axis xyz="0 1 0"/>
    <dynamics damping="0" friction="0"/>
    <limit effort="60" lower="-3.141592653" upper="3.141592653" velocity="52.4"/>
  </joint>

  <joint name="FR_knee_joint" type="fixed" dont_collapse="true">
    <origin rpy="0 0 0"  xyz="0 0 -0.3260342677986043"/>
    <parent link="FR_thigh"/>
    <child link="FR_knee"/>
  </joint>

  <joint name="FR_calf_joint" type="revolute">
    <origin rpy="0 0 0"  xyz="0 0 0"/>
    <parent link="FR_knee"/>
    <child link="FR_calf"/>
    <axis xyz="0 1 0"/>
    <dynamics damping="0" friction="0"/>
    <limit effort="60" lower="-3.141592653" upper="3.141592653" velocity="52.4"/>
  </joint>

  <joint name="FR_foot_joint" type="fixed" dont_collapse="true">
    <origin rpy="0 0 0"  xyz="0 0 -0.2675220349037209"/>
    <parent link="FR_calf"/>
    <child link="FR_foot"/>
  </joint>

  <joint name="FL_hip_joint" type="revolute">
    <origin rpy="0 0 0"  xyz="0.34308860454049706 0.15171628482032276 -0.038178028851525284"/>
    <parent link="trunk"/>
    <child link="FL_hip"/>
    <axis xyz="1 0 0"/>
    <dynamics damping="0" friction="0"/>
    <limit effort="60" lower="-3.141592653" upper="3.141592653" velocity="52.4"/>
  </joint>

  <joint name="FL_thigh_joint" type="revolute">
    <origin rpy="0 0 0"  xyz="0 0 0"/>
    <parent link="FL_hip"/>
    <child link="FL_thigh"/>
    <axis xyz="0 1 0"/>
    <dynamics damping="0" friction="0"/>
    <limit effort="60" lower="-3.141592653" upper="3.141592653" velocity="52.4"/>
  </joint>

  <joint name="FL_knee_joint" type="fixed" dont_collapse="true">
    <origin rpy="0 0 0"  xyz="0 0 -0.3260342677986043"/>
    <parent link="FL_thigh"/>
    <child link="FL_knee"/>
  </joint>

  <joint name="FL_calf_joint" type="revolute">
    <origin rpy="0 0 0"  xyz="0 0 0"/>
    <parent link="FL_knee"/>
    <child link="FL_calf"/>
    <axis xyz="0 1 0"/>
    <dynamics damping="0" friction="0"/>
    <limit effort="60" lower="-3.141592653" upper="3.141592653" velocity="52.4"/>
  </joint>

  <joint name="FL_foot_joint" type="fixed" dont_collapse="true">
    <origin rpy="0 0 0"  xyz="0 0 -0.2675220349037209"/>
    <parent link="FL_calf"/>
    <child link="FL_foot"/>
  </joint>

  <joint name="RR_hip_joint" type="revolute">
    <origin rpy="0 0 0"  xyz="-0.34308860454049706 -0.15171628482032276 -0.038178028851525284"/>
    <parent link="trunk"/>
    <child link="RR_hip"/>
    <axis xyz="1 0 0"/>
    <dynamics damping="0" friction="0"/>
    <limit effort="60" lower="-3.141592653" upper="3.141592653" velocity="52.4"/>
  </joint>

  <joint name="RR_thigh_joint" type="revolute">
    <origin rpy="0 0 0"  xyz="0 0 0"/>
    <parent link="RR_hip"/>
    <child link="RR_thigh"/>
    <axis xyz="0 1 0"/>
    <dynamics damping="0" friction="0"/>
    <limit effort="60" lower="-3.141592653" upper="3.141592653" velocity="52.4"/>
  </joint>

  <joint name="RR_knee_joint" type="fixed" dont_collapse="true">
    <origin rpy="0 0 0"  xyz="0 0 -0.3260342677986043"/>
    <parent link="RR_thigh"/>
    <child link="RR_knee"/>
  </joint>

  <joint name="RR_calf_joint" type="revolute">
    <origin rpy="0 0 0"  xyz="0 0 0"/>
    <parent link="RR_knee"/>
    <child link="RR_calf"/>
    <axis xyz="0 1 0"/>
    <dynamics damping="0" friction="0"/>
    <limit effort="60" lower="-3.141592653" upper="3.141592653" velocity="52.4"/>
  </joint>

  <joint name="RR_foot_joint" type="fixed" dont_collapse="true">
    <origin rpy="0 0 0"  xyz="0 0 -0.2675220349037209"/>
    <parent link="RR_calf"/>
    <child link="RR_foot"/>
  </joint>

  <joint name="RL_hip_joint" type="revolute">
    <origin rpy="0 0 0"  xyz="-0.34308860454049706 0.15171628482032276 -0.038178028851525284"/>
    <parent link="trunk"/>
    <child link="RL_hip"/>
    <axis xyz="1 0 0"/>
    <dynamics damping="0" friction="0"/>
    <limit effort="60" lower="-3.141592653" upper="3.141592653" velocity="52.4"/>
  </joint>

  <joint name="RL_thigh_joint" type="revolute">
    <origin rpy="0 0 0"  xyz="0 0 0"/>
    <parent link="RL_hip"/>
    <child link="RL_thigh"/>
    <axis xyz="0 1 0"/>
    <dynamics damping="0" friction="0"/>
    <limit effort="60" lower="-3.141592653" upper="3.141592653" velocity="52.4"/>
  </joint>

  <joint name="RL_knee_joint" type="fixed" dont_collapse="true">
    <origin rpy="0 0 0"  xyz="0 0 -0.3260342677986043"/>
    <parent link="RL_thigh"/>
    <child link="RL_knee"/>
  </joint>

  <joint name="RL_calf_joint" type="revolute">
    <origin rpy="0 0 0"  xyz="0 0 0"/>
    <parent link="RL_knee"/>
    <child link="RL_calf"/>
    <axis xyz="0 1 0"/>
    <dynamics damping="0" friction="0"/>
    <limit effort="60" lower="-3.141592653" upper="3.141592653" velocity="52.4"/>
  </joint>

  <joint name="RL_foot_joint" type="fixed" dont_collapse="true">
    <origin rpy="0 0 0"  xyz="0 0 -0.2675220349037209"/>
    <parent link="RL_calf"/>
    <child link="RL_foot"/>
  </joint>

 </robot> 